<?xml version="1.0" encoding="UTF-8"?>
<robot name="g1">
  <mujoco>
    <compiler meshdir="." balanceinertia="true" discardvisual="false"/>
  </mujoco> 
  <joint name="head_joint" type="fixed">
    <origin xyz="0. 0. 0." rpy="0. 0. 0."/>
    <parent link="torso_link"/>
    <child link="head_link"/>
  </joint>
  <joint name="imu_joint" type="fixed">
    <origin xyz="-0.0423387 0.00166 0.152067 " rpy="0. 0. 0."/>
    <parent link="torso_link"/>
    <child link="imu_link"/>
  </joint>
  <joint name="left_ankle_pitch_joint" type="revolute">
    <origin xyz="-0.0000004 0.0040687 -0.30007 " rpy="0. -0.1605288 0. "/>
    <parent link="left_knee_link"/>
    <child link="left_ankle_pitch_link"/>
    <axis xyz="0. 1. 0."/>
    <limit lower="-0.68" upper="0.73" effort="40." velocity="52.9999992"/>
  </joint>
  <joint name="left_ankle_roll_joint" type="revolute">
    <origin xyz="0.0000003 0. -0.017558 " rpy="0. -0.000001 0. "/>
    <parent link="left_ankle_pitch_link"/>
    <child link="left_ankle_roll_link"/>
    <axis xyz="1. 0. 0."/>
    <limit lower="-0.2618" upper="0.2618" effort="40." velocity="52.9999992"/>
  </joint>
  <joint name="left_elbow_pitch_joint" type="revolute">
    <origin xyz="0. 0.00189 -0.0855 " rpy="0. 0. 0."/>
    <parent link="left_shoulder_yaw_link"/>
    <child link="left_elbow_pitch_link"/>
    <axis xyz="0. 1. 0."/>
    <limit lower="-0.2268" upper="3.4207998" effort="21." velocity="52.9999992"/>
  </joint>
  <joint name="left_elbow_roll_joint" type="revolute">
    <origin xyz="0.1 0. 0. " rpy="0. 0. 0."/>
    <parent link="left_elbow_pitch_link"/>
    <child link="left_elbow_roll_link"/>
    <axis xyz="1. 0. 0."/>
    <limit lower="-2.0942999" upper="2.0942999" effort="21." velocity="52.9999992"/>
  </joint>
  <joint name="left_five_joint" type="revolute">
    <origin xyz="0.02395 0.004 0.085 " rpy="0. -1.5707963 0. "/>
    <parent link="left_palm_link"/>
    <child link="left_five_link"/>
    <axis xyz="0. 0. 1."/>
    <limit lower="-1.84" upper="0.3" effort="0.7" velocity="23.0000009"/>
  </joint>
  <joint name="left_four_joint" type="revolute">
    <origin xyz="0.0471 -0.0036 -0. " rpy="0. 0. 0."/>
    <parent link="left_three_link"/>
    <child link="left_four_link"/>
    <axis xyz="0. 0. 1."/>
    <limit lower="-1.84" upper="0." effort="0.7" velocity="23.0000009"/>
  </joint>
  <joint name="left_hip_pitch_joint" type="revolute">
    <origin xyz="0. 0.06445 -0.1027 " rpy="0. -0.34907 0. "/>
    <parent link="g1"/>
    <child link="left_hip_pitch_link"/>
    <axis xyz="0. 1. 0."/>
    <limit lower="-2.3499997" upper="3.0499999" effort="88." velocity="32.0000004"/>
  </joint>
  <joint name="left_hip_roll_joint" type="revolute">
    <origin xyz="0. 0.0523 0. " rpy="0. -0.0000002 0. "/>
    <parent link="left_hip_pitch_link"/>
    <child link="left_hip_roll_link"/>
    <axis xyz="1. 0. 0."/>
    <limit lower="-0.26" upper="2.5299998" effort="88." velocity="32.0000004"/>
  </joint>
  <joint name="left_hip_yaw_joint" type="revolute">
    <origin xyz="0.01966 -0.0012139 -0.1241 " rpy="0. 0. 0."/>
    <parent link="left_hip_roll_link"/>
    <child link="left_hip_yaw_link"/>
    <axis xyz="0. 0. 1."/>
    <limit lower="-2.7499998" upper="2.7499998" effort="88." velocity="32.0000004"/>
  </joint>
  <joint name="left_knee_joint" type="revolute">
    <origin xyz="-0.078292 -0.0017335 -0.177225 " rpy="0. 0.5096 0. "/>
    <parent link="left_hip_yaw_link"/>
    <child link="left_knee_link"/>
    <axis xyz="0. 1. 0."/>
    <limit lower="-0.33489" upper="2.5448997" effort="139." velocity="20.000001"/>
  </joint>
  <joint name="left_one_joint" type="revolute">
    <origin xyz="-0.026525 -0.0188 -0.00005 " rpy="0. 0. 0."/>
    <parent link="left_zero_link"/>
    <child link="left_one_link"/>
    <axis xyz="0. 0. 1."/>
    <limit lower="-0.9999999" upper="1.2" effort="0.7" velocity="23.0000009"/>
  </joint>
  <joint name="left_palm_joint" type="fixed">
    <origin xyz="0.12 0. 0. " rpy="0. 1.5707963 0. "/>
    <parent link="left_elbow_roll_link"/>
    <child link="left_palm_link"/>
  </joint>
  <joint name="left_shoulder_pitch_joint" type="revolute">
    <origin xyz="-0.0025 0.10396 0.25928" rpy="0.27925 0. 0. "/>
    <parent link="torso_link"/>
    <child link="left_shoulder_pitch_link"/>
    <axis xyz="0. 1. 0."/>
    <limit lower="-2.9670997" upper="2.7924999" effort="21." velocity="52.9999992"/>
  </joint>
  <joint name="left_shoulder_roll_joint" type="revolute">
    <origin xyz="0. 0.052 0. " rpy="-0.2792497 0. 0. "/>
    <parent link="left_shoulder_pitch_link"/>
    <child link="left_shoulder_roll_link"/>
    <axis xyz="1. 0. 0."/>
    <limit lower="-1.5882" upper="2.2514998" effort="21." velocity="52.9999992"/>
  </joint>
  <joint name="left_shoulder_yaw_joint" type="revolute">
    <origin xyz="-0.00354 0.0062424 -0.1032 " rpy="-0.0000003 0. 0. "/>
    <parent link="left_shoulder_roll_link"/>
    <child link="left_shoulder_yaw_link"/>
    <axis xyz="0. 0. 1."/>
    <limit lower="-2.618" upper="2.618" effort="21." velocity="52.9999992"/>
  </joint>
  <joint name="left_six_joint" type="revolute">
    <origin xyz="0.0471 -0.0036 0. " rpy="0. 0. 0."/>
    <parent link="left_five_link"/>
    <child link="left_six_link"/>
    <axis xyz="0. 0. 1."/>
    <limit lower="-1.84" upper="0." effort="0.7" velocity="23.0000009"/>
  </joint>
  <joint name="left_three_joint" type="revolute">
    <origin xyz="-0.02395 0.004 0.085 " rpy="0. -1.5707963 0. "/>
    <parent link="left_palm_link"/>
    <child link="left_three_link"/>
    <axis xyz="0. 0. 1."/>
    <limit lower="-1.84" upper="0.3" effort="0.7" velocity="23.0000009"/>
  </joint>
  <joint name="left_two_joint" type="revolute">
    <origin xyz="0. -0.0431 0. " rpy="0. 0. 0."/>
    <parent link="left_one_link"/>
    <child link="left_two_link"/>
    <axis xyz="0. 0. 1."/>
    <limit lower="0." upper="1.84" effort="0.7" velocity="23.0000009"/>
  </joint>
  <joint name="left_zero_joint" type="revolute">
    <origin xyz="0. 0. 0.05" rpy="0. -1.5707963 0. "/>
    <parent link="left_palm_link"/>
    <child link="left_zero_link"/>
    <axis xyz="0. 1. 0."/>
    <limit lower="-0.523598" upper="0.523598" effort="0.7" velocity="23.0000009"/>
  </joint>
  <joint name="logo_joint" type="fixed">
    <origin xyz="0. 0. 0." rpy="0. 0. 0."/>
    <parent link="torso_link"/>
    <child link="logo_link"/>
  </joint>
  <joint name="pelvis_contour_joint" type="fixed">
    <origin xyz="0. 0. 0." rpy="0. 0. 0."/>
    <parent link="g1"/>
    <child link="pelvis_contour_link"/>
  </joint>
  <joint name="right_ankle_pitch_joint" type="revolute">
    <origin xyz="-0.0000004 -0.0040687 -0.30007 " rpy="0. -0.1605288 0. "/>
    <parent link="right_knee_link"/>
    <child link="right_ankle_pitch_link"/>
    <axis xyz="0. 1. 0."/>
    <limit lower="-0.68" upper="0.73" effort="40." velocity="52.9999992"/>
  </joint>
  <joint name="right_ankle_roll_joint" type="revolute">
    <origin xyz="0.0000003 -0. -0.017558 " rpy="0. -0.000001 0. "/>
    <parent link="right_ankle_pitch_link"/>
    <child link="right_ankle_roll_link"/>
    <axis xyz="1. 0. 0."/>
    <limit lower="-0.2618" upper="0.2618" effort="40." velocity="52.9999992"/>
  </joint>
  <joint name="right_elbow_pitch_joint" type="revolute">
    <origin xyz="0. -0.00189 -0.0855 " rpy="0. 0. 0."/>
    <parent link="right_shoulder_yaw_link"/>
    <child link="right_elbow_pitch_link"/>
    <axis xyz="0. 1. 0."/>
    <limit lower="-0.2268" upper="3.4207998" effort="21." velocity="52.9999992"/>
  </joint>
  <joint name="right_elbow_roll_joint" type="revolute">
    <origin xyz="0.1 -0. 0. " rpy="0. 0. 0."/>
    <parent link="right_elbow_pitch_link"/>
    <child link="right_elbow_roll_link"/>
    <axis xyz="1. 0. 0."/>
    <limit lower="-2.0942999" upper="2.0942999" effort="21." velocity="52.9999992"/>
  </joint>
  <joint name="right_five_joint" type="revolute">
    <origin xyz="0.02395 -0.004 0.085 " rpy="0. -1.5707963 0. "/>
    <parent link="right_palm_link"/>
    <child link="right_five_link"/>
    <axis xyz="0. 0. 1."/>
    <limit lower="-0.3" upper="1.84" effort="0.7" velocity="23.0000009"/>
  </joint>
  <joint name="right_four_joint" type="revolute">
    <origin xyz="0.0471 0.0036 -0. " rpy="0. 0. 0."/>
    <parent link="right_three_link"/>
    <child link="right_four_link"/>
    <axis xyz="0. 0. 1."/>
    <limit lower="0." upper="1.84" effort="0.7" velocity="23.0000009"/>
  </joint>
  <joint name="right_hip_pitch_joint" type="revolute">
    <origin xyz="0. -0.06445 -0.1027 " rpy="0. -0.34907 0. "/>
    <parent link="g1"/>
    <child link="right_hip_pitch_link"/>
    <axis xyz="0. 1. 0."/>
    <limit lower="-2.3499997" upper="3.0499999" effort="88." velocity="32.0000004"/>
  </joint>
  <joint name="right_hip_roll_joint" type="revolute">
    <origin xyz="0. -0.0523 0. " rpy="0. -0.0000002 0. "/>
    <parent link="right_hip_pitch_link"/>
    <child link="right_hip_roll_link"/>
    <axis xyz="1. 0. 0."/>
    <limit lower="-2.5299998" upper="0.26" effort="88." velocity="32.0000004"/>
  </joint>
  <joint name="right_hip_yaw_joint" type="revolute">
    <origin xyz="0.01966 0.0012139 -0.1241 " rpy="0. 0. 0."/>
    <parent link="right_hip_roll_link"/>
    <child link="right_hip_yaw_link"/>
    <axis xyz="0. 0. 1."/>
    <limit lower="-2.7499998" upper="2.7499998" effort="88." velocity="32.0000004"/>
  </joint>
  <joint name="right_knee_joint" type="revolute">
    <origin xyz="-0.078292 0.0017335 -0.177225 " rpy="0. 0.5096 0. "/>
    <parent link="right_hip_yaw_link"/>
    <child link="right_knee_link"/>
    <axis xyz="0. 1. 0."/>
    <limit lower="-0.33489" upper="2.5448997" effort="139." velocity="20.000001"/>
  </joint>
  <joint name="right_one_joint" type="revolute">
    <origin xyz="-0.026525 0.0188 -0.00005 " rpy="0. 0. 0."/>
    <parent link="right_zero_link"/>
    <child link="right_one_link"/>
    <axis xyz="0. 0. 1."/>
    <limit lower="-1.2" upper="0.9999999" effort="0.7" velocity="23.0000009"/>
  </joint>
  <joint name="right_palm_joint" type="fixed">
    <origin xyz="0.12 0. 0. " rpy="0. 1.5707963 0. "/>
    <parent link="right_elbow_roll_link"/>
    <child link="right_palm_link"/>
  </joint>
  <joint name="right_shoulder_pitch_joint" type="revolute">
    <origin xyz="-0.0025 -0.10396 0.25928" rpy="-0.27925 0. 0. "/>
    <parent link="torso_link"/>
    <child link="right_shoulder_pitch_link"/>
    <axis xyz="0. 1. 0."/>
    <limit lower="-2.9670997" upper="2.7924999" effort="21." velocity="52.9999992"/>
  </joint>
  <joint name="right_shoulder_roll_joint" type="revolute">
    <origin xyz="0. -0.052 0. " rpy="0.2792497 0. 0. "/>
    <parent link="right_shoulder_pitch_link"/>
    <child link="right_shoulder_roll_link"/>
    <axis xyz="1. 0. 0."/>
    <limit lower="-2.2514998" upper="1.5882" effort="21." velocity="52.9999992"/>
  </joint>
  <joint name="right_shoulder_yaw_joint" type="revolute">
    <origin xyz="-0.00354 -0.0062424 -0.1032 " rpy="0.0000003 0. 0. "/>
    <parent link="right_shoulder_roll_link"/>
    <child link="right_shoulder_yaw_link"/>
    <axis xyz="0. 0. 1."/>
    <limit lower="-2.618" upper="2.618" effort="21." velocity="52.9999992"/>
  </joint>
  <joint name="right_six_joint" type="revolute">
    <origin xyz="0.0471 0.0036 0. " rpy="0. 0. 0."/>
    <parent link="right_five_link"/>
    <child link="right_six_link"/>
    <axis xyz="0. 0. 1."/>
    <limit lower="0." upper="1.84" effort="0.7" velocity="23.0000009"/>
  </joint>
  <joint name="right_three_joint" type="revolute">
    <origin xyz="-0.02395 -0.004 0.085 " rpy="0. -1.5707963 0. "/>
    <parent link="right_palm_link"/>
    <child link="right_three_link"/>
    <axis xyz="0. 0. 1."/>
    <limit lower="-0.3" upper="1.84" effort="0.7" velocity="23.0000009"/>
  </joint>
  <joint name="right_two_joint" type="revolute">
    <origin xyz="0. 0.0431 0. " rpy="0. 0. 0."/>
    <parent link="right_one_link"/>
    <child link="right_two_link"/>
    <axis xyz="0. 0. 1."/>
    <limit lower="-1.84" upper="0." effort="0.7" velocity="23.0000009"/>
  </joint>
  <joint name="right_zero_joint" type="revolute">
    <origin xyz="0. 0. 0.05" rpy="0. -1.5707963 0. "/>
    <parent link="right_palm_link"/>
    <child link="right_zero_link"/>
    <axis xyz="0. 1. 0."/>
    <limit lower="-0.523598" upper="0.523598" effort="0.7" velocity="23.0000009"/>
  </joint>
  <joint name="torso_joint" type="revolute">
    <origin xyz="0. 0. 0." rpy="0. 0. 0."/>
    <parent link="g1"/>
    <child link="torso_link"/>
    <axis xyz="0. 0. 1."/>
    <limit lower="-2.618" upper="2.618" effort="88." velocity="32.0000004"/>
  </joint>
  <link name="g1">
    <visual>
      <origin xyz="0. 0. 0." rpy="0. 0. 0."/>
      <geometry>
        <mesh filename="pelvis_visuals.obj" scale="1. 1. 1."/>
      </geometry>
    </visual>
    <collision>
      <origin xyz="0. 0. 0." rpy="0. 0. 0."/>
      <geometry>
        <mesh filename="pelvis_collisions.obj" scale="1. 1. 1."/>
      </geometry>
    </collision>
  </link>
  <link name="head_link">
    <inertial>
      <origin xyz="0.0013807 0.0002843 0.4203419" rpy="0. 0. 0."/>
      <mass value="1.1797652"/>
      <inertia ixx="0.0054324" ixy="0.0000014" ixz="0.0003455" iyy="0.0055289" iyz="0.000015" izz="0.0016538"/>
    </inertial>
    <visual>
      <origin xyz="0. 0. 0." rpy="0. 0. 0."/>
      <geometry>
        <mesh filename="head_link_visuals.obj" scale="1. 1. 1."/>
      </geometry>
    </visual>
    <collision>
      <origin xyz="0. 0. 0." rpy="0. 0. 0."/>
      <geometry>
        <mesh filename="head_link_collisions.obj" scale="1. 1. 1."/>
      </geometry>
    </collision>
  </link>
  <link name="imu_link">
    <inertial>
      <origin xyz="-inf -inf -inf" rpy="0. 0. 0."/>
      <mass value="0.000001"/>
      <inertia ixx="0.00001" ixy="0." ixz="0." iyy="0.00001" iyz="0." izz="0.00001"/>
    </inertial>
  </link>
  <link name="left_ankle_pitch_link">
    <inertial>
      <origin xyz="-0.007269 0. 0.011137" rpy="0. 0. 0."/>
      <mass value="0.074"/>
      <inertia ixx="0.0000084" ixy="0." ixz="-0.0000029" iyy="0.0000189" iyz="0." izz="0.0000126"/>
    </inertial>
    <visual>
      <origin xyz="0.0000003 0. 0. " rpy="0. -0.000001 0. "/>
      <geometry>
        <mesh filename="left_ankle_pitch_link_visuals.obj" scale="1. 1. 1."/>
      </geometry>
    </visual>
    <collision>
      <origin xyz="0.0000003 0. 0. " rpy="0. -0.000001 0. "/>
      <geometry>
        <mesh filename="left_ankle_pitch_link_collisions.obj" scale="1. 1. 1."/>
      </geometry>
    </collision>
  </link>
  <link name="left_ankle_roll_link">
    <inertial>
      <origin xyz="0.024762 0.00002 -0.012526" rpy="0. 0. 0."/>
      <mass value="0.391"/>
      <inertia ixx="0.0001552" ixy="-0.0000001" ixz="0.0000751" iyy="0.0010657" iyz="0.0000001" izz="0.001098"/>
    </inertial>
    <visual>
      <origin xyz="0. 0. 0." rpy="0. 0. 0."/>
      <geometry>
        <mesh filename="left_ankle_roll_link_visuals.obj" scale="1. 1. 1."/>
      </geometry>
    </visual>
    <collision>
      <origin xyz="0. 0. 0." rpy="0. 0. 0."/>
      <geometry>
        <mesh filename="left_ankle_roll_link_collisions.obj" scale="1. 1. 1."/>
      </geometry>
    </collision>
  </link>
  <link name="left_elbow_pitch_link">
    <inertial>
      <origin xyz="0.064497 0.002873 0. " rpy="0. 0. 0."/>
      <mass value="0.601"/>
      <inertia ixx="0.0002845" ixy="0.0000806" ixz="0." iyy="0.0004647" iyz="0." izz="0.0004712"/>
    </inertial>
    <visual>
      <origin xyz="0. 0. 0." rpy="0. 0. 0."/>
      <geometry>
        <mesh filename="left_elbow_pitch_link_visuals.obj" scale="1. 1. 1."/>
      </geometry>
    </visual>
    <collision>
      <origin xyz="0. 0. 0." rpy="0. 0. 0."/>
      <geometry>
        <mesh filename="left_elbow_pitch_link_collisions.obj" scale="1. 1. 1."/>
      </geometry>
    </collision>
  </link>
  <link name="left_elbow_roll_link">
    <inertial>
      <origin xyz="0.081811 0.001454 0.001 " rpy="0. 0. 0."/>
      <mass value="0.227"/>
      <inertia ixx="0.0001093" ixy="-0.0000155" ixz="-0.0000291" iyy="0.000977" iyz="0.000001" izz="0.0009676"/>
    </inertial>
    <visual>
      <origin xyz="-0. 0. 0." rpy="0. 0. 0."/>
      <geometry>
        <mesh filename="left_elbow_roll_link_visuals.obj" scale="1. 1. 1."/>
      </geometry>
    </visual>
    <collision>
      <origin xyz="-0. 0. 0." rpy="0. 0. 0."/>
      <geometry>
        <mesh filename="left_elbow_roll_link_collisions.obj" scale="1. 1. 1."/>
      </geometry>
    </collision>
  </link>
  <link name="left_five_link">
    <inertial>
      <origin xyz="0.0362561 -0.0015725 0.0002699" rpy="0. 0. 0."/>
      <mass value="0.0488469"/>
      <inertia ixx="0.0000038" ixy="0." ixz="0." iyy="0.0000089" iyz="-0." izz="0.0000087"/>
    </inertial>
    <visual>
      <origin xyz="-0. -0. 0." rpy="0. 0. 0."/>
      <geometry>
        <mesh filename="left_five_link_visuals.obj" scale="1. 1. 1."/>
      </geometry>
    </visual>
    <collision>
      <origin xyz="-0. -0. 0." rpy="0. 0. 0."/>
      <geometry>
        <mesh filename="left_five_link_collisions.obj" scale="1. 1. 1."/>
      </geometry>
    </collision>
  </link>
  <link name="left_four_link">
    <inertial>
      <origin xyz="0.0237591 0.0013526 0.0001197" rpy="0. 0. 0."/>
      <mass value="0.0138583"/>
      <inertia ixx="0.0000009" ixy="-0.0000001" ixz="0." iyy="0.0000025" iyz="-0." izz="0.000002"/>
    </inertial>
    <visual>
      <origin xyz="-0. -0. 0." rpy="0. 0. 0."/>
      <geometry>
        <mesh filename="left_four_link_visuals.obj" scale="1. 1. 1."/>
      </geometry>
    </visual>
    <collision>
      <origin xyz="-0. -0. 0." rpy="0. 0. 0."/>
      <geometry>
        <mesh filename="left_four_link_collisions.obj" scale="1. 1. 1."/>
      </geometry>
    </collision>
  </link>
  <link name="left_hip_pitch_link">
    <inertial>
      <origin xyz="0.001962 0.049392 -0.000941" rpy="0. 0. 0."/>
      <mass value="1.299"/>
      <inertia ixx="0.0013873" ixy="-0.0000163" ixz="-0.000001" iyy="0.0009059" iyz="-0.0000424" izz="0.0009196"/>
    </inertial>
    <visual>
      <origin xyz="0. 0. 0." rpy="0. -0.0000002 0. "/>
      <geometry>
        <mesh filename="left_hip_pitch_link_visuals.obj" scale="1. 1. 1."/>
      </geometry>
    </visual>
    <collision>
      <origin xyz="0. 0. 0." rpy="0. -0.0000002 0. "/>
      <geometry>
        <mesh filename="left_hip_pitch_link_collisions.obj" scale="1. 1. 1."/>
      </geometry>
    </collision>
  </link>
  <link name="left_hip_roll_link">
    <inertial>
      <origin xyz="0.024757 -0.001036 -0.086323" rpy="0. 0. 0."/>
      <mass value="1.446"/>
      <inertia ixx="0.0022702" ixy="-0.0000037" ixz="-0.0003789" iyy="0.002304" iyz="-0.000018" izz="0.0016001"/>
    </inertial>
    <visual>
      <origin xyz="0. 0. 0." rpy="0. 0. 0."/>
      <geometry>
        <mesh filename="left_hip_roll_link_visuals.obj" scale="1. 1. 1."/>
      </geometry>
    </visual>
    <collision>
      <origin xyz="0. 0. 0." rpy="0. 0. 0."/>
      <geometry>
        <mesh filename="left_hip_roll_link_collisions.obj" scale="1. 1. 1."/>
      </geometry>
    </collision>
  </link>
  <link name="left_hip_yaw_link">
    <inertial>
      <origin xyz="-0.053554 -0.011477 -0.14067 " rpy="0. 0. 0."/>
      <mass value="2.052"/>
      <inertia ixx="0.0087264" ixy="-0.0004402" ixz="-0.0036676" iyy="0.011374" iyz="-0.0006654" izz="0.004279"/>
    </inertial>
    <visual>
      <origin xyz="-0. -0. 0." rpy="0. 0. 0."/>
      <geometry>
        <mesh filename="left_hip_yaw_link_visuals.obj" scale="1. 1. 1."/>
      </geometry>
    </visual>
    <collision>
      <origin xyz="-0. -0. 0." rpy="0. 0. 0."/>
      <geometry>
        <mesh filename="left_hip_yaw_link_collisions.obj" scale="1. 1. 1."/>
      </geometry>
    </collision>
  </link>
  <link name="left_knee_link">
    <inertial>
      <origin xyz="0.005505 0.006534 -0.116629" rpy="0. 0. 0."/>
      <mass value="2.2520001"/>
      <inertia ixx="0.0124438" ixy="0.0000535" ixz="-0.0004376" iyy="0.0126749" iyz="-0.0006825" izz="0.0019865"/>
    </inertial>
    <visual>
      <origin xyz="-0. 0. 0." rpy="0. 0.0000012 0. "/>
      <geometry>
        <mesh filename="left_knee_link_visuals.obj" scale="1. 1. 1."/>
      </geometry>
    </visual>
    <collision>
      <origin xyz="0.0069998 0.005 -0.15 " rpy="0. 0.0000012 0. "/>
      <geometry>
        <cylinder radius="0.015" length="0.15"/>
      </geometry>
    </collision>
  </link>
  <link name="left_one_link">
    <inertial>
      <origin xyz="-0.0018154 -0.0327057 -0.0001859" rpy="0. 0. 0."/>
      <mass value="0.047762"/>
      <inertia ixx="0.000008" ixy="-0.0000002" ixz="-0." iyy="0.0000037" iyz="0.0000001" izz="0.0000079"/>
    </inertial>
    <visual>
      <origin xyz="0. 0. 0." rpy="0. 0. 0."/>
      <geometry>
        <mesh filename="left_one_link_visuals.obj" scale="1. 1. 1."/>
      </geometry>
    </visual>
    <collision>
      <origin xyz="-0.001 -0.032 0. " rpy="0. 0. 0."/>
      <geometry>
        <box size="0.02 0.03 0.02"/>
      </geometry>
    </collision>
  </link>
  <link name="left_palm_link">
    <inertial>
      <origin xyz="0.0557842 0.0014851 -0.0003267" rpy="0. 0. 0."/>
      <mass value="0.2812604"/>
      <inertia ixx="0.0001764" ixy="-0.0000065" ixz="0.0000002" iyy="0.0003108" iyz="0." izz="0.0001894"/>
    </inertial>
    <visual>
      <origin xyz="0. 0. -0." rpy="0. -1.5707963 0. "/>
      <geometry>
        <mesh filename="left_palm_link_visuals.obj" scale="1. 1. 1."/>
      </geometry>
    </visual>
    <collision>
      <origin xyz="0. 0. -0." rpy="0. -1.5707963 0. "/>
      <geometry>
        <mesh filename="left_palm_link_collisions.obj" scale="1. 1. 1."/>
      </geometry>
    </collision>
  </link>
  <link name="left_shoulder_pitch_link">
    <inertial>
      <origin xyz="-0.001431 0.048811 0.001304" rpy="0. 0. 0."/>
      <mass value="0.713"/>
      <inertia ixx="0.0004614" ixy="-0.0000093" ixz="0.00001" iyy="0.0004146" iyz="0.0000055" izz="0.0004416"/>
    </inertial>
    <visual>
      <origin xyz="0. 0. 0." rpy="0.0000003 0. 0. "/>
      <geometry>
        <mesh filename="left_shoulder_pitch_link_visuals.obj" scale="1. 1. 1."/>
      </geometry>
    </visual>
    <collision>
      <origin xyz="0. 0. 0." rpy="0.0000003 0. 0. "/>
      <geometry>
        <mesh filename="left_shoulder_pitch_link_collisions.obj" scale="1. 1. 1."/>
      </geometry>
    </collision>
  </link>
  <link name="left_shoulder_roll_link">
    <inertial>
      <origin xyz="-0.003415 0.006955 -0.064598" rpy="0. 0. 0."/>
      <mass value="0.642"/>
      <inertia ixx="0.0006159" ixy="-0." ixz="-0.0000056" iyy="0.0006835" iyz="0.0000021" izz="0.000373"/>
    </inertial>
    <visual>
      <origin xyz="0. -0. -0." rpy="-0.0000003 0. 0. "/>
      <geometry>
        <mesh filename="left_shoulder_roll_link_visuals.obj" scale="1. 1. 1."/>
      </geometry>
    </visual>
    <collision>
      <origin xyz="-0.004 0.006 -0.053" rpy="-0.0000003 0. 0. "/>
      <geometry>
        <cylinder radius="0.03" length="0.03"/>
      </geometry>
    </collision>
  </link>
  <link name="left_shoulder_yaw_link">
    <inertial>
      <origin xyz="0.000375 -0.00444 -0.072374" rpy="0. 0. 0."/>
      <mass value="0.713"/>
      <inertia ixx="0.0009699" ixy="0.0000071" ixz="0.0000078" iyy="0.0009691" iyz="-0.0000449" izz="0.0003826"/>
    </inertial>
    <visual>
      <origin xyz="0. -0. 0." rpy="0. 0. 0."/>
      <geometry>
        <mesh filename="left_shoulder_yaw_link_visuals.obj" scale="1. 1. 1."/>
      </geometry>
    </visual>
    <collision>
      <origin xyz="0. -0. 0." rpy="0. 0. 0."/>
      <geometry>
        <mesh filename="left_shoulder_yaw_link_collisions.obj" scale="1. 1. 1."/>
      </geometry>
    </collision>
  </link>
  <link name="left_six_link">
    <inertial>
      <origin xyz="0.0237591 0.0013526 0.0001197" rpy="0. 0. 0."/>
      <mass value="0.0138583"/>
      <inertia ixx="0.0000009" ixy="-0.0000001" ixz="0." iyy="0.0000025" iyz="-0." izz="0.000002"/>
    </inertial>
    <visual>
      <origin xyz="-0. -0. 0." rpy="0. 0. 0."/>
      <geometry>
        <mesh filename="left_six_link_visuals.obj" scale="1. 1. 1."/>
      </geometry>
    </visual>
    <collision>
      <origin xyz="-0. -0. 0." rpy="0. 0. 0."/>
      <geometry>
        <mesh filename="left_six_link_collisions.obj" scale="1. 1. 1."/>
      </geometry>
    </collision>
  </link>
  <link name="left_three_link">
    <inertial>
      <origin xyz="0.0362561 -0.0015725 0.0002699" rpy="0. 0. 0."/>
      <mass value="0.0488469"/>
      <inertia ixx="0.0000038" ixy="0." ixz="0." iyy="0.0000089" iyz="-0." izz="0.0000087"/>
    </inertial>
    <visual>
      <origin xyz="-0. -0. -0." rpy="0. 0. 0."/>
      <geometry>
        <mesh filename="left_three_link_visuals.obj" scale="1. 1. 1."/>
      </geometry>
    </visual>
    <collision>
      <origin xyz="-0. -0. -0." rpy="0. 0. 0."/>
      <geometry>
        <mesh filename="left_three_link_collisions.obj" scale="1. 1. 1."/>
      </geometry>
    </collision>
  </link>
  <link name="left_two_link">
    <inertial>
      <origin xyz="-0.0013526 -0.0237591 -0.0001197" rpy="0. 0. 0."/>
      <mass value="0.0138583"/>
      <inertia ixx="0.0000025" ixy="-0.0000001" ixz="-0." iyy="0.0000009" iyz="0." izz="0.000002"/>
    </inertial>
    <visual>
      <origin xyz="0. 0. 0." rpy="0. 0. 0."/>
      <geometry>
        <mesh filename="left_two_link_visuals.obj" scale="1. 1. 1."/>
      </geometry>
    </visual>
    <collision>
      <origin xyz="0. 0. 0." rpy="0. 0. 0."/>
      <geometry>
        <mesh filename="left_two_link_collisions.obj" scale="1. 1. 1."/>
      </geometry>
    </collision>
  </link>
  <link name="left_zero_link">
    <inertial>
      <origin xyz="-0.0260466 -0.0087751 0.0000109" rpy="0. 0. 0."/>
      <mass value="0.0509893"/>
      <inertia ixx="0.0000068" ixy="-0.000001" ixz="-0." iyy="0.000005" iyz="0." izz="0.0000087"/>
    </inertial>
    <visual>
      <origin xyz="0. 0. 0." rpy="0. 0. 0."/>
      <geometry>
        <mesh filename="left_zero_link_visuals.obj" scale="1. 1. 1."/>
      </geometry>
    </visual>
  </link>
  <link name="logo_link">
    <inertial>
      <origin xyz="-0.0030656 0.0000563 0.2452646" rpy="0. 0. 0."/>
      <mass value="0.001"/>
      <inertia ixx="0.0000009" ixy="0.0000001" ixz="0." iyy="0.0000064" iyz="0." izz="0.0000069"/>
    </inertial>
    <visual>
      <origin xyz="0. 0. 0." rpy="0. 0. 0."/>
      <geometry>
        <mesh filename="logo_link_visuals.obj" scale="1. 1. 1."/>
      </geometry>
    </visual>
    <collision>
      <origin xyz="0. 0. 0." rpy="0. 0. 0."/>
      <geometry>
        <mesh filename="logo_link_collisions.obj" scale="1. 1. 1."/>
      </geometry>
    </collision>
  </link>
  <link name="pelvis_contour_link">
    <inertial>
      <origin xyz="-inf -inf -inf" rpy="0. 0. 0."/>
      <mass value="0.000001"/>
      <inertia ixx="0.00001" ixy="0." ixz="0." iyy="0.00001" iyz="0." izz="0.00001"/>
    </inertial>
    <visual>
      <origin xyz="0. 0. 0." rpy="0. 0. 0."/>
      <geometry>
        <mesh filename="pelvis_contour_link_visuals.obj" scale="1. 1. 1."/>
      </geometry>
    </visual>
  </link>
  <link name="right_ankle_pitch_link">
    <inertial>
      <origin xyz="-0.007269 0. 0.011137" rpy="0. 0. 0."/>
      <mass value="0.074"/>
      <inertia ixx="0.0000084" ixy="0." ixz="-0.0000029" iyy="0.0000189" iyz="0." izz="0.0000126"/>
    </inertial>
    <visual>
      <origin xyz="0.0000003 -0. 0. " rpy="0. -0.000001 0. "/>
      <geometry>
        <mesh filename="right_ankle_pitch_link_visuals.obj" scale="1. 1. 1."/>
      </geometry>
    </visual>
    <collision>
      <origin xyz="0.0000003 -0. 0. " rpy="0. -0.000001 0. "/>
      <geometry>
        <mesh filename="right_ankle_pitch_link_collisions.obj" scale="1. 1. 1."/>
      </geometry>
    </collision>
  </link>
  <link name="right_ankle_roll_link">
    <inertial>
      <origin xyz="0.024762 -0.00002 -0.012526" rpy="0. 0. 0."/>
      <mass value="0.391"/>
      <inertia ixx="0.0001552" ixy="0.0000001" ixz="0.0000751" iyy="0.0010657" iyz="-0.0000001" izz="0.001098"/>
    </inertial>
    <visual>
      <origin xyz="0. 0. 0." rpy="0. 0. 0."/>
      <geometry>
        <mesh filename="right_ankle_roll_link_visuals.obj" scale="1. 1. 1."/>
      </geometry>
    </visual>
    <collision>
      <origin xyz="0. 0. 0." rpy="0. 0. 0."/>
      <geometry>
        <mesh filename="right_ankle_roll_link_collisions.obj" scale="1. 1. 1."/>
      </geometry>
    </collision>
  </link>
  <link name="right_elbow_pitch_link">
    <inertial>
      <origin xyz="0.064497 -0.002873 0. " rpy="0. 0. 0."/>
      <mass value="0.601"/>
      <inertia ixx="0.0002845" ixy="-0.0000806" ixz="0." iyy="0.0004647" iyz="-0." izz="0.0004712"/>
    </inertial>
    <visual>
      <origin xyz="0. -0. 0." rpy="0. 0. 0."/>
      <geometry>
        <mesh filename="right_elbow_pitch_link_visuals.obj" scale="1. 1. 1."/>
      </geometry>
    </visual>
    <collision>
      <origin xyz="0. -0. 0." rpy="0. 0. 0."/>
      <geometry>
        <mesh filename="right_elbow_pitch_link_collisions.obj" scale="1. 1. 1."/>
      </geometry>
    </collision>
  </link>
  <link name="right_elbow_roll_link">
    <inertial>
      <origin xyz="0.081811 -0.001454 0.001 " rpy="0. 0. 0."/>
      <mass value="0.227"/>
      <inertia ixx="0.0001093" ixy="0.0000155" ixz="-0.0000291" iyy="0.000977" iyz="-0.000001" izz="0.0009676"/>
    </inertial>
    <visual>
      <origin xyz="-0. 0. 0." rpy="0. 0. 0."/>
      <geometry>
        <mesh filename="right_elbow_roll_link_visuals.obj" scale="1. 1. 1."/>
      </geometry>
    </visual>
    <collision>
      <origin xyz="-0. 0. 0." rpy="0. 0. 0."/>
      <geometry>
        <mesh filename="right_elbow_roll_link_collisions.obj" scale="1. 1. 1."/>
      </geometry>
    </collision>
  </link>
  <link name="right_five_link">
    <inertial>
      <origin xyz="0.0362561 0.0015725 0.0002699" rpy="0. 0. 0."/>
      <mass value="0.0488469"/>
      <inertia ixx="0.0000038" ixy="-0." ixz="0." iyy="0.0000089" iyz="0." izz="0.0000087"/>
    </inertial>
    <visual>
      <origin xyz="-0. 0. 0." rpy="0. 0. 0."/>
      <geometry>
        <mesh filename="right_five_link_visuals.obj" scale="1. 1. 1."/>
      </geometry>
    </visual>
    <collision>
      <origin xyz="-0. 0. 0." rpy="0. 0. 0."/>
      <geometry>
        <mesh filename="right_five_link_collisions.obj" scale="1. 1. 1."/>
      </geometry>
    </collision>
  </link>
  <link name="right_four_link">
    <inertial>
      <origin xyz="0.0237591 -0.0013526 0.0001197" rpy="0. 0. 0."/>
      <mass value="0.0138583"/>
      <inertia ixx="0.0000009" ixy="0.0000001" ixz="0." iyy="0.0000025" iyz="0." izz="0.000002"/>
    </inertial>
    <visual>
      <origin xyz="-0. 0. 0." rpy="0. 0. 0."/>
      <geometry>
        <mesh filename="right_four_link_visuals.obj" scale="1. 1. 1."/>
      </geometry>
    </visual>
    <collision>
      <origin xyz="-0. 0. 0." rpy="0. 0. 0."/>
      <geometry>
        <mesh filename="right_four_link_collisions.obj" scale="1. 1. 1."/>
      </geometry>
    </collision>
  </link>
  <link name="right_hip_pitch_link">
    <inertial>
      <origin xyz="0.001962 -0.049392 -0.000941" rpy="0. 0. 0."/>
      <mass value="1.299"/>
      <inertia ixx="0.0013873" ixy="0.0000163" ixz="-0.000001" iyy="0.0009059" iyz="0.0000424" izz="0.0009196"/>
    </inertial>
    <visual>
      <origin xyz="0. 0. 0." rpy="0. -0.0000002 0. "/>
      <geometry>
        <mesh filename="right_hip_pitch_link_visuals.obj" scale="1. 1. 1."/>
      </geometry>
    </visual>
    <collision>
      <origin xyz="0. 0. 0." rpy="0. -0.0000002 0. "/>
      <geometry>
        <mesh filename="right_hip_pitch_link_collisions.obj" scale="1. 1. 1."/>
      </geometry>
    </collision>
  </link>
  <link name="right_hip_roll_link">
    <inertial>
      <origin xyz="0.024757 0.001036 -0.086323" rpy="0. 0. 0."/>
      <mass value="1.446"/>
      <inertia ixx="0.0022702" ixy="0.0000037" ixz="-0.0003789" iyy="0.002304" iyz="0.000018" izz="0.0016001"/>
    </inertial>
    <visual>
      <origin xyz="0. 0. 0." rpy="0. 0. 0."/>
      <geometry>
        <mesh filename="right_hip_roll_link_visuals.obj" scale="1. 1. 1."/>
      </geometry>
    </visual>
    <collision>
      <origin xyz="0. 0. 0." rpy="0. 0. 0."/>
      <geometry>
        <mesh filename="right_hip_roll_link_collisions.obj" scale="1. 1. 1."/>
      </geometry>
    </collision>
  </link>
  <link name="right_hip_yaw_link">
    <inertial>
      <origin xyz="-0.053554 0.011477 -0.14067 " rpy="0. 0. 0."/>
      <mass value="2.052"/>
      <inertia ixx="0.0087264" ixy="0.0004402" ixz="-0.0036676" iyy="0.011374" iyz="0.0006654" izz="0.004279"/>
    </inertial>
    <visual>
      <origin xyz="-0. 0. 0." rpy="0. 0. 0."/>
      <geometry>
        <mesh filename="right_hip_yaw_link_visuals.obj" scale="1. 1. 1."/>
      </geometry>
    </visual>
    <collision>
      <origin xyz="-0. 0. 0." rpy="0. 0. 0."/>
      <geometry>
        <mesh filename="right_hip_yaw_link_collisions.obj" scale="1. 1. 1."/>
      </geometry>
    </collision>
  </link>
  <link name="right_knee_link">
    <inertial>
      <origin xyz="0.005505 -0.006534 -0.116629" rpy="0. 0. 0."/>
      <mass value="2.2520001"/>
      <inertia ixx="0.0124438" ixy="-0.0000535" ixz="-0.0004376" iyy="0.0126749" iyz="0.0006825" izz="0.0019865"/>
    </inertial>
    <visual>
      <origin xyz="-0. -0. 0." rpy="0. 0.0000012 0. "/>
      <geometry>
        <mesh filename="right_knee_link_visuals.obj" scale="1. 1. 1."/>
      </geometry>
    </visual>
    <collision>
      <origin xyz="0.0069998 -0.005 -0.15 " rpy="0. 0.0000012 0. "/>
      <geometry>
        <cylinder radius="0.015" length="0.15"/>
      </geometry>
    </collision>
  </link>
  <link name="right_one_link">
    <inertial>
      <origin xyz="-0.0018154 0.0327057 -0.0001859" rpy="0. 0. 0."/>
      <mass value="0.047762"/>
      <inertia ixx="0.000008" ixy="0.0000002" ixz="-0." iyy="0.0000037" iyz="-0.0000001" izz="0.0000079"/>
    </inertial>
    <visual>
      <origin xyz="0. 0. 0." rpy="0. 0. 0."/>
      <geometry>
        <mesh filename="right_one_link_visuals.obj" scale="1. 1. 1."/>
      </geometry>
    </visual>
    <collision>
      <origin xyz="-0.001 0.032 0. " rpy="0. 0. 0."/>
      <geometry>
        <box size="0.02 0.03 0.02"/>
      </geometry>
    </collision>
  </link>
  <link name="right_palm_link">
    <inertial>
      <origin xyz="0.0557842 -0.0014851 -0.0003267" rpy="0. 0. 0."/>
      <mass value="0.2812604"/>
      <inertia ixx="0.0001764" ixy="0.0000065" ixz="0.0000002" iyy="0.0003108" iyz="-0." izz="0.0001894"/>
    </inertial>
    <visual>
      <origin xyz="0. 0. -0." rpy="0. -1.5707963 0. "/>
      <geometry>
        <mesh filename="right_palm_link_visuals.obj" scale="1. 1. 1."/>
      </geometry>
    </visual>
    <collision>
      <origin xyz="0. 0. -0." rpy="0. -1.5707963 0. "/>
      <geometry>
        <mesh filename="right_palm_link_collisions.obj" scale="1. 1. 1."/>
      </geometry>
    </collision>
  </link>
  <link name="right_shoulder_pitch_link">
    <inertial>
      <origin xyz="-0.001431 -0.048811 0.001304" rpy="0. 0. 0."/>
      <mass value="0.713"/>
      <inertia ixx="0.0004614" ixy="0.0000093" ixz="0.00001" iyy="0.0004146" iyz="-0.0000055" izz="0.0004416"/>
    </inertial>
    <visual>
      <origin xyz="0. 0. 0." rpy="-0.0000003 0. 0. "/>
      <geometry>
        <mesh filename="right_shoulder_pitch_link_visuals.obj" scale="1. 1. 1."/>
      </geometry>
    </visual>
    <collision>
      <origin xyz="0. 0. 0." rpy="-0.0000003 0. 0. "/>
      <geometry>
        <mesh filename="right_shoulder_pitch_link_collisions.obj" scale="1. 1. 1."/>
      </geometry>
    </collision>
  </link>
  <link name="right_shoulder_roll_link">
    <inertial>
      <origin xyz="-0.003415 -0.006955 -0.064598" rpy="0. 0. 0."/>
      <mass value="0.642"/>
      <inertia ixx="0.0006159" ixy="0." ixz="-0.0000056" iyy="0.0006835" iyz="-0.0000021" izz="0.000373"/>
    </inertial>
    <visual>
      <origin xyz="0. 0. -0." rpy="0.0000003 0. 0. "/>
      <geometry>
        <mesh filename="right_shoulder_roll_link_visuals.obj" scale="1. 1. 1."/>
      </geometry>
    </visual>
    <collision>
      <origin xyz="-0.004 -0.006 -0.053" rpy="0.0000003 0. 0. "/>
      <geometry>
        <cylinder radius="0.03" length="0.03"/>
      </geometry>
    </collision>
  </link>
  <link name="right_shoulder_yaw_link">
    <inertial>
      <origin xyz="0.000375 0.00444 -0.072374" rpy="0. 0. 0."/>
      <mass value="0.713"/>
      <inertia ixx="0.0009699" ixy="-0.0000071" ixz="0.0000078" iyy="0.0009691" iyz="0.0000449" izz="0.0003826"/>
    </inertial>
    <visual>
      <origin xyz="0. 0. 0." rpy="0. 0. 0."/>
      <geometry>
        <mesh filename="right_shoulder_yaw_link_visuals.obj" scale="1. 1. 1."/>
      </geometry>
    </visual>
    <collision>
      <origin xyz="0. 0. 0." rpy="0. 0. 0."/>
      <geometry>
        <mesh filename="right_shoulder_yaw_link_collisions.obj" scale="1. 1. 1."/>
      </geometry>
    </collision>
  </link>
  <link name="right_six_link">
    <inertial>
      <origin xyz="0.0237591 -0.0013526 0.0001197" rpy="0. 0. 0."/>
      <mass value="0.0138583"/>
      <inertia ixx="0.0000009" ixy="0.0000001" ixz="0." iyy="0.0000025" iyz="0." izz="0.000002"/>
    </inertial>
    <visual>
      <origin xyz="-0. 0. 0." rpy="0. 0. 0."/>
      <geometry>
        <mesh filename="right_six_link_visuals.obj" scale="1. 1. 1."/>
      </geometry>
    </visual>
    <collision>
      <origin xyz="-0. 0. 0." rpy="0. 0. 0."/>
      <geometry>
        <mesh filename="right_six_link_collisions.obj" scale="1. 1. 1."/>
      </geometry>
    </collision>
  </link>
  <link name="right_three_link">
    <inertial>
      <origin xyz="0.0362561 0.0015725 0.0002699" rpy="0. 0. 0."/>
      <mass value="0.0488469"/>
      <inertia ixx="0.0000038" ixy="-0." ixz="0." iyy="0.0000089" iyz="0." izz="0.0000087"/>
    </inertial>
    <visual>
      <origin xyz="-0. 0. -0." rpy="0. 0. 0."/>
      <geometry>
        <mesh filename="right_three_link_visuals.obj" scale="1. 1. 1."/>
      </geometry>
    </visual>
    <collision>
      <origin xyz="-0. 0. -0." rpy="0. 0. 0."/>
      <geometry>
        <mesh filename="right_three_link_collisions.obj" scale="1. 1. 1."/>
      </geometry>
    </collision>
  </link>
  <link name="right_two_link">
    <inertial>
      <origin xyz="-0.0013526 0.0237591 -0.0001197" rpy="0. 0. 0."/>
      <mass value="0.0138583"/>
      <inertia ixx="0.0000025" ixy="0.0000001" ixz="-0." iyy="0.0000009" iyz="-0." izz="0.000002"/>
    </inertial>
    <visual>
      <origin xyz="0. -0. 0." rpy="0. 0. 0."/>
      <geometry>
        <mesh filename="right_two_link_visuals.obj" scale="1. 1. 1."/>
      </geometry>
    </visual>
    <collision>
      <origin xyz="0. -0. 0." rpy="0. 0. 0."/>
      <geometry>
        <mesh filename="right_two_link_collisions.obj" scale="1. 1. 1."/>
      </geometry>
    </collision>
  </link>
  <link name="right_zero_link">
    <inertial>
      <origin xyz="-0.0260466 0.0087751 0.0000109" rpy="0. 0. 0."/>
      <mass value="0.0509893"/>
      <inertia ixx="0.0000068" ixy="0.000001" ixz="-0." iyy="0.000005" iyz="-0." izz="0.0000087"/>
    </inertial>
    <visual>
      <origin xyz="0. 0. 0." rpy="0. 0. 0."/>
      <geometry>
        <mesh filename="right_zero_link_visuals.obj" scale="1. 1. 1."/>
      </geometry>
    </visual>
  </link>
  <link name="torso_link">
    <inertial>
      <origin xyz="0.0019712 0.002669 0.1693651" rpy="0. 0. 0."/>
      <mass value="6.3395982"/>
      <inertia ixx="0.0603708" ixy="-0.0001017" ixz="0.0006985" iyy="0.0435515" iyz="0.0003437" izz="0.0333998"/>
    </inertial>
    <visual>
      <origin xyz="0. 0. 0." rpy="0. 0. 0."/>
      <geometry>
        <mesh filename="torso_link_visuals.obj" scale="1. 1. 1."/>
      </geometry>
    </visual>
    <collision>
      <origin xyz="0. 0. 0." rpy="0. 0. 0."/>
      <geometry>
        <mesh filename="torso_link_collisions.obj" scale="1. 1. 1."/>
      </geometry>
    </collision>
  </link>
</robot>
